<?xml version="1.0"?>
<robot xmlns:xacro="http://www.ros.org/wiki/xacro" name="barista_robot">

    <xacro:property name="robot_name" value="$(arg robot_name)"/>

    <xacro:include filename="$(find barista_robot_description)/xacro/barista_robot.gazebo.xacro" />
    <xacro:include filename="$(find barista_robot_description)/xacro/wheel.xacro" />
    <xacro:include filename="$(find barista_robot_description)/xacro/standoff.xacro" />
    <xacro:include filename="$(find barista_robot_description)/xacro/cup_holder_tray.xacro" />

    <xacro:property name="base_radius" value="0.178"/>
    <xacro:property name="base_length" value="0.155"/>
    <xacro:property name="base_mass" value="2.35"/>

    <xacro:property name="wheel_radius" value="0.0352"/>
    <xacro:property name="wheel_length" value="0.0206"/>
    <xacro:property name="wheel_mass" value="0.2"/>
    <xacro:property name="wheel_friction" value="1.0"/>
    <xacro:property name="wheel_damping" value="1.0"/>
    <xacro:property name="wheel_effort_limit" value="10000"/>
    <xacro:property name="wheel_velocity_limit" value="1000"/>

    <xacro:property name="caster_radius" value="0.0352"/>
    <xacro:property name="caster_mass" value="0.05"/>
    <xacro:property name="caster_friction" value="0.1"/>
    <xacro:property name="caster_damping" value="0.0"/>
    <xacro:property name="caster_effort_limit" value="1000.0"/>
    <xacro:property name="caster_velocity_limit" value="100.0"/>

    <xacro:property name="standoff_radius" value="0.010"/>
    <xacro:property name="standoff_length" value="0.220"/>
    <xacro:property name="standoff_mass" value="0.05"/>

    <xacro:property name="cup_holder_tray_radius" value="0.160"/>
    <xacro:property name="cup_holder_tray_length" value="0.090"/>
    <xacro:property name="cup_holder_tray_mass" value="0.5"/>
    <xacro:property name="cup_holder_tray_z_offset" value="0.3425"/>

    <xacro:property name="include_laser" value="true"/>

    <xacro:property name="rick_color" value="0.0 0.0 0.5 1"/>
    <xacro:property name="morty_color" value="0.5 0.0 0.0 1"/>

    <material name="rick_material">
        <color rgba="${rick_color}"/>
    </material>

    <material name="morty_material">
        <color rgba="${morty_color}"/>
    </material>

    <material name="gray">
        <color rgba="0.5 0.5 0.5 1.0"/> 
    </material>

    <material name="black">
        <color rgba="0.0 0.0 0.0 1"/>
    </material>

    <!-- main body -->

    <link name="base_link">
        <visual>
            <geometry>
                <cylinder radius="${base_radius}" length="${base_length}"/>
            </geometry>
            <material name="${robot_name}_material"/>
        </visual>

        <collision>
            <origin rpy="0 0 0" xyz="0 0 0"/>
            <geometry>
                <cylinder radius="${base_radius}" length="${base_length}"/>
            </geometry>
        </collision>

        <inertial>
            <origin rpy="0 0 0" xyz="0 0 0"/>
            <mass value="${base_mass}"/>
            <inertia ixx="0.01392573958333333" ixy="0" ixz="0" iyy="0.01392573958333333" iyz="0" izz="0.02650260416666667"/>
        </inertial>
    </link>


    <!-- Left Wheel -->

    <xacro:wheel wheel_name="left_wheel" />

    <joint name="joint_left_wheel" type="continuous">
        <origin rpy="0 0 0" xyz="0 0.128 -0.0775"/>
        <child link="left_wheel"/>
        <parent link="base_link"/>
        <axis rpy="0 0 0" xyz="0 1 0"/>
        <limit effort="10000" velocity="1000"/>
        <joint_properties damping="1.0" friction="1.0"/>
    </joint>

    <!-- Right Wheel -->

    <xacro:wheel wheel_name="right_wheel" />

    <joint name="joint_right_wheel" type="continuous">
        <origin rpy="0 0 0" xyz="0 -0.128 -0.0775"/>
        <child link="right_wheel"/>
        <parent link="base_link"/>
        <axis rpy="0 0 0" xyz="0 1 0"/>
        <limit effort="10000" velocity="1000"/>
        <joint_properties damping="1.0" friction="1.0"/>
    </joint>


    <!-- Caster Wheel Front -->

    <link name="front_yaw_link">
        <visual>
            <origin rpy="0 1.5707 1.5707" xyz="0 0 0"/>
            <geometry>
            <cylinder length="0.001" radius="0.0045000000000000005"/>
            </geometry>
            <material name="gray"/>
        </visual>
        <collision>
            <origin rpy="0 1.5707 1.5707" xyz="0 0 0"/>
            <geometry>
            <cylinder length="0.001" radius="0.0045000000000000005"/>
            </geometry>
        </collision>
        <inertial>
            <origin rpy="0 1.5707 1.5707" xyz="0 0 0"/>
            <mass value="0.001"/>
            <inertia ixx="5.145833333333334e-09" ixy="0" ixz="0" iyy="5.145833333333334e-09" iyz="0" izz="1.0125000000000003e-08"/>
        </inertial>
    </link>

    <joint name="front_yaw_joint" type="continuous">
        <origin rpy="0 0 0" xyz="0.120 0 -0.0775" />
        <parent link="base_link" />
        <child link="front_yaw_link" />
        <axis xyz="0 0 1" />
        <limit effort="${caster_effort_limit}" velocity="${caster_velocity_limit}" />
        <dynamics damping="${caster_damping}" friction="${caster_friction}"/>
    </joint>

    <link name="front_roll_link">
        <visual>
            <origin rpy="0 1.5707 1.5707" xyz="0 0 0"/>
            <geometry>
            <cylinder length="0.001" radius="0.0045000000000000005"/>
            </geometry>
            <material name="gray"/>
        </visual>
        <collision>
            <origin rpy="0 1.5707 1.5707" xyz="0 0 0"/>
            <geometry>
            <cylinder length="0.001" radius="0.0045000000000000005"/>
            </geometry>
        </collision>
        <inertial>
            <origin rpy="0 1.5707 1.5707" xyz="0 0 0"/>
            <mass value="0.001"/>
            <inertia ixx="5.145833333333334e-09" ixy="0" ixz="0" iyy="5.145833333333334e-09" iyz="0" izz="1.0125000000000003e-08"/>
        </inertial>
    </link>

    <joint name="front_roll_joint" type="continuous">
        <origin rpy="0 0 0" xyz="0 0 0" />
        <parent link="front_yaw_link" />
        <child link="front_roll_link" />
        <axis xyz="1 0 0" />
        <limit effort="${caster_effort_limit}" velocity="${caster_velocity_limit}" />
        <dynamics damping="${caster_damping}" friction="${caster_friction}"/>
    </joint>

    <link name="front_pitch_link">
        <visual>
            <origin rpy="0 1.5707 1.5707" xyz="0 0 0"/>
            <geometry>
            <sphere radius="${caster_radius}"/>
            </geometry>
            <material name="gray"/>
        </visual>
        <collision>
            <origin rpy="0 1.5707 1.5707" xyz="0 0 0"/>
            <geometry>
            <sphere radius="${caster_radius}"/>
            </geometry>
        </collision>
        <inertial>
            <origin rpy="0 1.5707 1.5707" xyz="0 0 0"/>
            <mass value="${caster_mass}"/>
            <inertia ixx="1.531733333333333e-05" ixy="0" ixz="0" iyy="1.531733333333333e-05" iyz="0" izz="1.531733333333333e-05"/>
        </inertial>
    </link>

    <joint name="front_pitch_joint" type="continuous">
        <origin rpy="0 0 0" xyz="0 0 0" />
        <parent link="front_roll_link" />
        <child link="front_pitch_link" />
        <axis xyz="0 1 0" />
        <limit effort="${caster_effort_limit}" velocity="${caster_velocity_limit}" />
        <dynamics damping="${caster_damping}" friction="${caster_friction}"/>
    </joint>

    <!-- Caster Wheel Back -->

    <link name="back_yaw_link">
        <visual>
            <origin rpy="0 1.5707 1.5707" xyz="0 0 0"/>
            <geometry>
            <cylinder length="0.001" radius="0.0045000000000000005"/>
            </geometry>
            <material name="gray"/>
        </visual>
        <collision>
            <origin rpy="0 1.5707 1.5707" xyz="0 0 0"/>
            <geometry>
            <cylinder length="0.001" radius="0.0045000000000000005"/>
            </geometry>
        </collision>
        <inertial>
            <origin rpy="0 1.5707 1.5707" xyz="0 0 0"/>
            <mass value="0.001"/>
            <inertia ixx="5.145833333333334e-09" ixy="0" ixz="0" iyy="5.145833333333334e-09" iyz="0" izz="1.0125000000000003e-08"/>
        </inertial>
    </link>

    <joint name="back_yaw_joint" type="continuous">
        <origin rpy="0 0 0" xyz="-0.120 0 -0.0775" />
        <parent link="base_link" />
        <child link="back_yaw_link" />
        <axis xyz="0 0 1" />
        <limit effort="${caster_effort_limit}" velocity="${caster_velocity_limit}" />
        <dynamics damping="${caster_damping}" friction="${caster_friction}"/>
    </joint>

    <link name="back_roll_link">
        <visual>
            <origin rpy="0 1.5707 1.5707" xyz="0 0 0"/>
            <geometry>
            <cylinder length="0.001" radius="0.0045000000000000005"/>
            </geometry>
            <material name="gray"/>
        </visual>
        <collision>
            <origin rpy="0 1.5707 1.5707" xyz="0 0 0"/>
            <geometry>
            <cylinder length="0.001" radius="0.0045000000000000005"/>
            </geometry>
        </collision>
        <inertial>
            <origin rpy="0 1.5707 1.5707" xyz="0 0 0"/>
            <mass value="0.001"/>
            <inertia ixx="5.145833333333334e-09" ixy="0" ixz="0" iyy="5.145833333333334e-09" iyz="0" izz="1.0125000000000003e-08"/>
        </inertial>
    </link>

    <joint name="back_roll_joint" type="continuous">
        <origin rpy="0 0 0" xyz="0 0 0" />
        <parent link="back_yaw_link" />
        <child link="back_roll_link" />
        <axis xyz="1 0 0" />
        <limit effort="${caster_effort_limit}" velocity="${caster_velocity_limit}" />
        <dynamics damping="${caster_damping}" friction="${caster_friction}"/>
    </joint>

    <link name="back_pitch_link">
        <visual>
            <origin rpy="0 1.5707 1.5707" xyz="0 0 0"/>
            <geometry>
            <sphere radius="${caster_radius}"/>
            </geometry>
            <material name="gray"/>
        </visual>
        <collision>
            <origin rpy="0 1.5707 1.5707" xyz="0 0 0"/>
            <geometry>
            <sphere radius="${caster_radius}"/>
            </geometry>
        </collision>
        <inertial>
            <origin rpy="0 1.5707 1.5707" xyz="0 0 0"/>
            <mass value="${caster_mass}"/>
            <inertia ixx="1.531733333333333e-05" ixy="0" ixz="0" iyy="1.531733333333333e-05" iyz="0" izz="1.531733333333333e-05"/>
        </inertial>
    </link>

    <joint name="back_pitch_joint" type="continuous">
        <origin rpy="0 0 0" xyz="0 0 0" />
        <parent link="back_roll_link" />
        <child link="back_pitch_link" />
        <axis xyz="0 1 0" />
        <limit effort="${caster_effort_limit}" velocity="${caster_velocity_limit}" />
        <dynamics damping="${caster_damping}" friction="${caster_friction}"/>
    </joint>


   <!-- Standoff Rod 1 -->

    <xacro:standoff_rod rod_name="standoff_rod_1" />

    <joint name="joint_standoff_rod_1" type="fixed">
        <origin rpy="0 0 0" xyz="0.100 0.100 0.1875"/>
        <parent link="base_link"/>
        <child link="standoff_rod_1"/>
    </joint>

    <!-- Standoff Rod 2 -->

    <xacro:standoff_rod rod_name="standoff_rod_2" />

    <joint name="joint_standoff_rod_2" type="fixed">
        <origin rpy="0 0 0" xyz="-0.100 0.100 0.1875"/>
        <parent link="base_link"/>
        <child link="standoff_rod_2"/>
    </joint>

    <!-- Standoff Rod 3 -->

    <xacro:standoff_rod rod_name="standoff_rod_3" />

    <joint name="joint_standoff_rod_3" type="fixed">
        <origin rpy="0 0 0" xyz="-0.100 -0.100 0.1875"/>
        <parent link="base_link"/>
        <child link="standoff_rod_3"/>
    </joint>

    <!-- Standoff Rod 4 -->

    <xacro:standoff_rod rod_name="standoff_rod_4" />

    <joint name="joint_standoff_rod_4" type="fixed">
        <origin rpy="0 0 0" xyz="0.100 -0.100 0.1875"/>
        <parent link="base_link"/>
        <child link="standoff_rod_4"/>
    </joint>


    <!-- Top Base -->

    <xacro:cup_holder_tray tray_z_pos="${cup_holder_tray_z_offset}" />

    <joint name="joint_cup_holder_tray" type="fixed">
        <origin rpy="0 0 0" xyz="0 0 0.3425"/>
        <parent link="base_link"/>
        <child link="cup_holder_tray"/>
    </joint>

    <!-- Laser Scanner -->

    <xacro:macro name="laser_scanner" params="include_laser">
        <xacro:if value="${include_laser}">
            <link name="laser_scan_link">
                <visual>
                <origin rpy="0 0 0" xyz="0 0 0"/>
                <geometry>
                    <mesh filename="package://barista_robot_description/models/hokuyo_urg_04lx.dae" scale="1.0 1.0 1.0"/>
                </geometry>
                </visual>
                <collision>
                <origin rpy="0 0 0" xyz="0 0 0.0204"/>
                <geometry>
                    <box size="0.074986 0.074935 0.0408"/>
                </geometry>
                </collision>
                <inertial>
                <mass value="0.01"/>
                <origin rpy="0 0 0" xyz="0 0 0.0204"/>
                <inertia ixx="6.066578520833334e-06" ixy="0" ixz="0" iyy="6.072950163333333e-06" iyz="0" izz="9.365128684166666e-06"/>
                </inertial>
            </link>

            <joint name="laser_scan_link_joint" type="fixed">
                <origin rpy="0 0 0" xyz="0.115 0.0 0.065"/>
                <parent link="base_link"/>
                <child link="laser_scan_link"/>
            </joint>

            <link name="laser_scan_frame"></link>

            <joint name="laser_scan_frame_joint" type="fixed">
                <origin rpy="0 0 0" xyz="0 0 0.055"/>
                <parent link="laser_scan_link"/>
                <child link="laser_scan_frame"/>
            </joint>
        </xacro:if>
    </xacro:macro>

    <xacro:laser_scanner include_laser="${include_laser}" />

    <xacro:gazebo_elements />

</robot>